Workbook

Sheet merchants
A1: merchant_id | B1: merchant_name | C1: category | D1: region
A2: 1 | B2: Merchant_001 | C2: ecommerce | D2: South
A3: 2 | B3: Merchant_002 | C3: grocery | D3: West
A4: 3 | B4: Merchant_003 | C4: grocery | D4: East
A5: 4 | B5: Merchant_004 | C5: ecommerce | D5: East
A6: 5 | B6: Merchant_005 | C6: recharge | D6: South
A7: 6 | B7: Merchant_006 | C7: food_delivery | D7: South
A8: 7 | B8: Merchant_007 | C8: food_delivery | D8: East
A9: 8 | B9: Merchant_008 | C9: food_delivery | D9: North
A10: 9 | B10: Merchant_009 | C10: ecommerce | D10: North
A11: 10 | B11: Merchant_010 | C11: grocery | D11: West
A12: 11 | B12: Merchant_011 | C12: ecommerce | D12: North
A13: 12 | B13: Merchant_012 | C13: ecommerce | D13: East
... A41: 40 | B41: Merchant_040 | C41: entertainment | D41: South

Sheet Summary_Pivot
B3: Column Labels
B4: captured | D4: chargeback | F4: failed | H4: Total Count of transaction_id | I4: Total Sum of amount_inr
A5: Row Labels | B5: Count of transaction_id | C5: Sum of amount_inr | D5: Count of transaction_id | E5: Sum of amount_inr | F5: Count of transaction_id | G5: Sum of amount_inr
A6: 1 | B6: 8 | C6: 10142 | F6: 1 | G6: 299 | H6: 9 | I6: 10441
A7: ecommerce | B7: 8 | C7: 10142 | F7: 1 | G7: 299 | H7: 9 | I7: 10441
A8: 2 | B8: 10 | C8: 3640 | H8: 10 | I8: 3640
A9: grocery | B9: 10 | C9: 3640 | H9: 10 | I9: 3640
A10: 3 | B10: 16 | C10: 8084 | D10: 1 | E10: 149 | H10: 17 | I10: 8233
A11: grocery | B11: 16 | C11: 8084 | D11: 1 | E11: 149 | H11: 17 | I11: 8233
A12: 4 | B12: 9 | C12: 6941 | H12: 9 | I12: 6941
A13: ecommerce | B13: 9 | C13: 6941 | H13: 9 | I13: 6941
A14: 5 | B14: 10 | C14: 5340 | F14: 1 | G14: 499 | H14: 11 | I14: 5839
A15: recharge | B15: 10 | C15: 5340 | F15: 1 | G15: 499 | H15: 11 | I15: 5839
A16: 6 | B16: 13 | C16: 6637 | D16: 1 | E16: 799 | H16: 14 | I16: 7436
A17: food_delivery | B17: 13 | C17: 6637 | D17: 1 | E17: 799 | H17: 14 | I17: 7436
A18: 7 | B18: 12 | C18: 11638 | D18: 1 | E18: 1999 | F18: 3 | G18: 2297 | H18: 16 | I18: 15934
A19: food_delivery | B19: 12 | C19: 11638 | D19: 1 | E19: 1999 | F19: 3 | G19: 2297 | H19: 16 | I19: 15934
A20: 8 | B20: 14 | C20: 7086 | D20: 1 | E20: 49 | F20: 1 | G20: 299 | H20: 16 | I20: 7434
A21: food_delivery | B21: 14 | C21: 7086 | D21: 1 | E21: 49 | F21: 1 | G21: 299 | H21: 16 | I21: 7434
A22: 9 | B22: 15 | C22: 4485 | F22: 3 | G22: 497 | H22: 18 | I22: 4982
A23: ecommerce | B23: 15 | C23: 4485 | F23: 3 | G23: 497 | H23: 18 | I23: 4982
A24: 10 | B24: 11 | C24: 7639 | D24: 2 | E24: 5048 | F24: 1 | G24: 399 | H24: 14 | I24: 13086
A25: grocery | B25: 11 | C25: 7639 | D25: 2 | E25: 5048 | F25: 1 | G25: 399 | H25: 14 | I25: 13086
A26: 11 | B26: 8 | C26: 9292 | D26: 1 | E26: 149 | F26: 1 | G26: 1499 | H26: 10 | I26: 10940
A27: ecommerce | B27: 8 | C27: 9292 | D27: 1 | E27: 149 | F27: 1 | G27: 1499 | H27: 10 | I27: 10940
A28: 12 | B28: 11 | C28: 9389 | F28: 2 | G28: 998 | H28: 13 | I28: 10387
A29: ecommerce | B29: 11 | C29: 9389 | F29: 2 | G29: 998 | H29: 13 | I29: 10387
A30: 13 | B30: 10 | C30: 10390 | D30: 1 | E30: 4999 | F30: 1 | G30: 2999 | H30: 12 | I30: 18388
A31: travel | B31: 10 | C31: 10390 | D31: 1 | E31: 4999 | F31: 1 | G31: 2999 | H31: 12 | I31: 18388
A32: 14 | B32: 11 | C32: 6189 | F32: 1 | G32: 299 | H32: 12 | I32: 6488
A33: grocery | B33: 11 | C33: 6189 | F33: 1 | G33: 299 | H33: 12 | I33: 6488
A34: 15 | B34: 11 | C34: 7439 | F34: 1 | G34: 399 | H34: 12 | I34: 7838
A35: travel | B35: 11 | C35: 7439 | F35: 1 | G35: 399 | H35: 12 | I35: 7838
A36: 16 | B36: 17 | C36: 10183 | F36: 3 | G36: 947 | H36: 20 | I36: 11130
A37: bill_payment | B37: 17 | C37: 10183 | F37: 3 | G37: 947 | H37: 20 | I37: 11130
A38: 17 | B38: 12 | C38: 12738 | F38: 1 | G38: 299 | H38: 13 | I38: 13037
A39: grocery | B39: 12 | C39: 12738 | F39: 1 | G39: 299 | H39: 13 | I39: 13037
A40: 18 | B40: 11 | C40: 7089 | H40: 11 | I40: 7089
A41: grocery | B41: 11 | C41: 7089 | H41: 11 | I41: 7089
A42: 19 | B42: 11 | C42: 7239 | D42: 1 | E42: 4999 | F42: 2 | G42: 598 | H42: 14 | I42: 12836
...

Sheet transactions
A1: transaction_id | B1: user_id | C1: merchant_id | D1: merchant_name | E1: category | F1: region | G1: transaction_time | H1: amount_inr | I1: payment_method | J1: status | K1: risk_score | L1: MDR fee(INR) | M1: merchant_status_tag
A2: TXN100000 | B2: 350 | C2: 16 | D2: =IFERROR(VLOOKUP(C2, merchants!$A$2:$D$41, 2, FALSE), "Merchant not found") -> Merchant_016 | E2: =IFERROR(VLOOKUP(C2, merchants!$A$2:$D$41, 3, FALSE), "Merchant not found") -> bill_payment | F2: =IFERROR(VLOOKUP(C2, merchants!$A$2:$D$41, 4, FALSE), "Merchant not found") -> West | G2: 46051.467 | H2: 2999 | I2: Wallet | J2: captured | K2: 85 | L2: =IFERROR(HLOOKUP(TRIM(I2), FeeTable!$B$1:$H$2, 2, FALSE) * H2, 0) -> 32.989 | M2: =IF(AND(H2 > 5000, F2 <> "East"), "High-Value Merchant Day", "Standard") -> Standard
A3: TXN100001 | B3: 287 | C3: 27 | D3: =IFERROR(VLOOKUP(C3, merchants!$A$2:$D$41, 2, FALSE), "Merchant not found") -> Merchant_027 | E3: =IFERROR(VLOOKUP(C3, merchants!$A$2:$D$41, 3, FALSE), "Merchant not found") -> ecommerce | F3: =IFERROR(VLOOKUP(C3, merchants!$A$2:$D$41, 4, FALSE), "Merchant not found") -> North | G3: 46026.492 | H3: 49 | I3: UPI | J3: captured | K3: 79 | L3: =IFERROR(HLOOKUP(TRIM(I3), FeeTable!$B$1:$H$2, 2, FALSE) * H3, 0) -> 0 | M3: =IF(AND(H3 > 5000, F3 <> "East"), "High-Value Merchant Day", "Standard") -> Standard
A4: TXN100002 | B4: 122 | C4: 11 | D4: =IFERROR(VLOOKUP(C4, merchants!$A$2:$D$41, 2, FALSE), "Merchant not found") -> Merchant_011 | E4: =IFERROR(VLOOKUP(C4, merchants!$A$2:$D$41, 3, FALSE), "Merchant not found") -> ecommerce | F4: =IFERROR(VLOOKUP(C4, merchants!$A$2:$D$41, 4, FALSE), "Merchant not found") -> North | G4: 46046.208 | H4: 1499 | I4: Wallet | J4: captured | K4: 22 | L4: =IFERROR(HLOOKUP(TRIM(I4), FeeTable!$B$1:$H$2, 2, FALSE) * H4, 0) -> 16.489 | M4: =IF(AND(H4 > 5000, F4 <> "East"), "High-Value Merchant Day", "Standard") -> Standard
A5: TXN100003 | B5: 92 | C5: 22 | D5: =IFERROR(VLOOKUP(C5, merchants!$A$2:$D$41, 2, FALSE), "Merchant not found") -> Merchant_022 | E5: =IFERROR(VLOOKUP(C5, merchants!$A$2:$D$41, 3, FALSE), "Merchant not found") -> travel | F5: =IFERROR(VLOOKUP(C5, merchants!$A$2:$D$41, 4, FALSE), "Merchant not found") -> South | G5: 46051.542 | H5: 49 | I5: Netbanking | J5: captured | K5: 100 | L5: =IFERROR(HLOOKUP(TRIM(I5), FeeTable!$B$1:$H$2, 2, FALSE) * H5, 0) -> 0.735 | M5: =IF(AND(H5 > 5000, F5 <> "East"), "High-Value Merchant Day", "Standard") -> Standard
A6: TXN100004 | B6: 343 | C6: 16 | D6: =IFERROR(VLOOKUP(C6, merchants!$A$2:$D$41, 2, FALSE), "Merchant not found") -> Merchant_016 | E6: =IFERROR(VLOOKUP(C6, merchants!$A$2:$D$41, 3, FALSE), "Merchant not found") -> bill_payment | F6: =IFERROR(VLOOKUP(C6, merchants!$A$2:$D$41, 4, FALSE), "Merchant not found") -> West | G6: 46052.577 | H6: 99 | I6: UPI | J6: captured | K6: 34 | L6: =IFERROR(HLOOKUP(TRIM(I6), FeeTable!$B$1:$H$2, 2, FALSE) * H6, 0) -> 0 | M6: =IF(AND(H6 > 5000, F6 <> "East"), "High-Value Merchant Day", "Standard") -> Standard
A7: TXN100005 | B7: 196 | C7: 3 | D7: =IFERROR(VLOOKUP(C7, merchants!$A$2:$D$41, 2, FALSE), "Merchant not found") -> Merchant_003 | E7: =IFERROR(VLOOKUP(C7, merchants!$A$2:$D$41, 3, FALSE), "Merchant not found") -> grocery | F7: =IFERROR(VLOOKUP(C7, merchants!$A$2:$D$41, 4, FALSE), "Merchant not found") -> East | G7: 46028.921 | H7: 99 | I7: UPI | J7: captured | K7: 60 | L7: =IFERROR(HLOOKUP(TRIM(I7), FeeTable!$B$1:$H$2, 2, FALSE) * H7, 0) -> 0 | M7: =IF(AND(H7 > 5000, F7 <> "East"), "High-Value Merchant Day", "Standard") -> Standard
A8: TXN100006 | B8: 236 | C8: 23 | D8: =IFERROR(VLOOKUP(C8, merchants!$A$2:$D$41, 2, FALSE), "Merchant not found") -> Merchant_023 | E8: =IFERROR(VLOOKUP(C8, merchants!$A$2:$D$41, 3, FALSE), "Merchant not found") -> travel | F8: =IFERROR(VLOOKUP(C8, merchants!$A$2:$D$41, 4, FALSE), "Merchant not found") -> North | G8: 46030.286 | H8: 99 | I8: Wallet | J8: captured | K8: 39 | L8: =IFERROR(HLOOKUP(TRIM(I8), FeeTable!$B$1:$H$2, 2, FALSE) * H8, 0) -> 1.089 | M8: =IF(AND(H8 > 5000, F8 <> "East"), "High-Value Merchant Day", "Standard") -> Standard
A9: TXN100007 | B9: 13 | C9: 13 | D9: =IFERROR(VLOOKUP(C9, merchants!$A$2:$D$41, 2, FALSE), "Merchant not found") -> Merchant_013 | E9: =IFERROR(VLOOKUP(C9, merchants!$A$2:$D$41, 3, FALSE), "Merchant not found") -> travel | F9: =IFERROR(VLOOKUP(C9, merchants!$A$2:$D$41, 4, FALSE), "Merchant not found") -> East | G9: 46049.301 | H9: 99 | I9: UPI | J9: captured | K9: 51 | L9: =IFERROR(HLOOKUP(TRIM(I9), FeeTable!$B$1:$H$2, 2, FALSE) * H9, 0) -> 0 | M9: =IF(AND(H9 > 5000, F9 <> "East"), "High-Value Merchant Day", "Standard") -> Standard
A10: TXN100008 | B10: 36 | C10: 18 | D10: =IFERROR(VLOOKUP(C10, merchants!$A$2:$D$41, 2, FALSE), "Merchant not found") -> Merchant_018 | E10: =IFERROR(VLOOKUP(C10, merchants!$A$2:$D$41, 3, FALSE), "Merchant not found") -> grocery | F10: =IFERROR(VLOOKUP(C10, merchants!$A$2:$D$41, 4, FALSE), "Merchant not found") -> West | G10: 46033.372 | H10: 799 | I10: UPI | J10: captured | K10: 44 | L10: =IFERROR(HLOOKUP(TRIM(I10), FeeTable!$B$1:$H$2, 2, FALSE) * H10, 0) -> 0 | M10: =IF(AND(H10 > 5000, F10 <> "East"), "High-Value Merchant Day", "Standard") -> Standard
A11: TXN100009 | B11: 348 | C11: 35 | D11: =IFERROR(VLOOKUP(C11, merchants!$A$2:$D$41, 2, FALSE), "Merchant not found") -> Merchant_035 | E11: =IFERROR(VLOOKUP(C11, merchants!$A$2:$D$41, 3, FALSE), "Merchant not found") -> recharge | F11: =IFERROR(VLOOKUP(C11, merchants!$A$2:$D$41, 4, FALSE), "Merchant not found") -> East | G11: 46043.684 | H11: 299 | I11: UPI | J11: captured | K11: 42 | L11: =IFERROR(HLOOKUP(TRIM(I11), FeeTable!$B$1:$H$2, 2, FALSE) * H11, 0) -> 0 | M11: =IF(AND(H11 > 5000, F11 <> "East"), "High-Value Merchant Day", "Standard") -> Standard
A12: TXN100010 | B12: 134 | C12: 12 | D12: =IFERROR(VLOOKUP(C12, merchants!$A$2:$D$41, 2, FALSE), "Merchant not found") -> Merchant_012 | E12: =IFERROR(VLOOKUP(C12, merchants!$A$2:$D$41, 3, FALSE), "Merchant not found") -> ecommerce | F12: =IFERROR(VLOOKUP(C12, merchants!$A$2:$D$41, 4, FALSE), "Merchant not found") -> East | G12: 46023.164 | H12: 49 | I12: UPI | J12: captured | K12: 74 | L12: =IFERROR(HLOOKUP(TRIM(I12), FeeTable!$B$1:$H$2, 2, FALSE) * H12, 0) -> 0 | M12: =IF(AND(H12 > 5000, F12 <> "East"), "High-Value Merchant Day", "Standard") -> Standard
A13: TXN100011 | B13: 306 | C13: 28 | D13: =IFERROR(VLOOKUP(C13, merchants!$A$2:$D$41, 2, FALSE), "Merchant not found") -> Merchant_028 | E13: =IFERROR(VLOOKUP(C13, merchants!$A$2:$D$41, 3, FALSE), "Merchant not found") -> ecommerce | F13: =IFERROR(VLOOKUP(C13, merchants!$A$2:$D$41, 4, FALSE), "Merchant not found") -> South | G13: 46031.046 | H13: 2999 | I13: Card | J13: failed | K13: 44 | L13: =IFERROR(HLOOKUP(TRIM(I13), FeeTable!$B$1:$H$2, 2, FALSE) * H13, 0) -> 53.982 | M13: =IF(AND(H13 > 5000, F13 <> "East"), "High-Value Merchant Day", "Standard") -> Standard
... A548: TXN300031 | B548: 345 | C548: 12 | D548: =IFERROR(VLOOKUP(C548, merchants!$A$2:$D$41, 2, FALSE), "Merchant not found") -> Merchant_012 | E548: =IFERROR(VLOOKUP(C548, merchants!$A$2:$D$41, 3, FALSE), "Merchant not found") -> ecommerce | F548: =IFERROR(VLOOKUP(C548, merchants!$A$2:$D$41, 4, FALSE), "Merchant not found") -> East | G548: 46045.377 | H548: 399 | I548: Card | J548: captured | K548: 69 | L548: =IFERROR(HLOOKUP(TRIM(I548), FeeTable!$B$1:$H$2, 2, FALSE) * H548, 0) -> 7.182 | M548: =IF(AND(H548 > 5000, F548 <> "East"), "High-Value Merchant Day", "Standard") -> Standard

Sheet FeeTable
A1: payment_method | B1: UPI | C1: Wallet | D1: Card | E1: NetBanking
A2: Fee% | B2: 0 | C2: 0.011 | D2: 0.018 | E2: 0.015
